<?xml version="1.0" encoding="utf-8"?>
<!-- =================================================================================== -->
<!-- |    This document was autogenerated by xacro from urdf/social_robot.urdf.xacro   | -->
<!-- |    EDITING THIS FILE BY HAND IS NOT RECOMMENDED                                 | -->
<!-- =================================================================================== -->
<robot name="social_robot" xmlns:xacro="http://ros.org/wiki/xacro">
  <!-- World -->
  <gazebo reference="world">
  </gazebo>
  <!-- Body -->
  <gazebo reference="base_link">
    <kp>1000000.0</kp>
    <kd>100.0</kd>
    <mu1>30.0</mu1>
    <mu2>30.0</mu2>
    <maxVel>1.0</maxVel>
    <minDepth>0.001</minDepth>
    <material>Gazebo/Grey</material>
  </gazebo>
  <gazebo reference="Waist_Pitch">
    <kp>1000000.0</kp>
    <kd>100.0</kd>
    <mu1>30.0</mu1>
    <mu2>30.0</mu2>
    <maxVel>1.0</maxVel>
    <minDepth>0.001</minDepth>
    <material>Gazebo/Grey</material>
  </gazebo>
  <!-- head -->
  <gazebo reference="Head_Yaw">
    <kp>1000000.0</kp>
    <kd>100.0</kd>
    <mu1>30.0</mu1>
    <mu2>30.0</mu2>
    <maxVel>1.0</maxVel>
    <minDepth>0.001</minDepth>
    <material>Gazebo/Grey</material>
  </gazebo>
  <gazebo reference="Head_Pitch">
    <kp>1000000.0</kp>
    <kd>100.0</kd>
    <mu1>30.0</mu1>
    <mu2>30.0</mu2>
    <maxVel>1.0</maxVel>
    <minDepth>0.001</minDepth>
    <material>Gazebo/Grey</material>
  </gazebo>
  <!-- left arm -->
  <gazebo reference="LShoulder_Pitch">
    <kp>1000000.0</kp>
    <kd>100.0</kd>
    <mu1>30.0</mu1>
    <mu2>30.0</mu2>
    <maxVel>1.0</maxVel>
    <minDepth>0.001</minDepth>
    <material>Gazebo/White</material>
  </gazebo>
  <gazebo reference="LShoulder_Roll">
    <kp>1000000.0</kp>
    <kd>100.0</kd>
    <mu1>30.0</mu1>
    <mu2>30.0</mu2>
    <maxVel>1.0</maxVel>
    <minDepth>0.001</minDepth>
    <material>Gazebo/White</material>
  </gazebo>
  <gazebo reference="LElbow_Pitch">
    <kp>1000000.0</kp>
    <kd>100.0</kd>
    <mu1>30.0</mu1>
    <mu2>30.0</mu2>
    <maxVel>1.0</maxVel>
    <minDepth>0.001</minDepth>
    <material>Gazebo/White</material>
  </gazebo>
  <gazebo reference="LElbow_Yaw">
    <kp>1000000.0</kp>
    <kd>100.0</kd>
    <mu1>30.0</mu1>
    <mu2>30.0</mu2>
    <maxVel>1.0</maxVel>
    <minDepth>0.001</minDepth>
    <material>Gazebo/White</material>
  </gazebo>
  <gazebo reference="LWrist_Pitch">
    <kp>1000000.0</kp>
    <kd>100.0</kd>
    <mu1>30.0</mu1>
    <mu2>30.0</mu2>
    <maxVel>1.0</maxVel>
    <minDepth>0.001</minDepth>
    <material>Gazebo/White</material>
  </gazebo>
  <gazebo reference="LWrist_Roll">
    <kp>1000000.0</kp>
    <kd>100.0</kd>
    <mu1>30.0</mu1>
    <mu2>30.0</mu2>
    <maxVel>1.0</maxVel>
    <minDepth>0.001</minDepth>
    <material>Gazebo/White</material>
  </gazebo>
  <!-- right arm -->
  <gazebo reference="RShoulder_Pitch">
    <kp>1000000.0</kp>
    <kd>100.0</kd>
    <mu1>30.0</mu1>
    <mu2>30.0</mu2>
    <maxVel>1.0</maxVel>
    <minDepth>0.001</minDepth>
    <material>Gazebo/White</material>
  </gazebo>
  <gazebo reference="RShoulder_Roll">
    <kp>1000000.0</kp>
    <kd>100.0</kd>
    <mu1>30.0</mu1>
    <mu2>30.0</mu2>
    <maxVel>1.0</maxVel>
    <minDepth>0.001</minDepth>
    <material>Gazebo/White</material>
  </gazebo>
  <gazebo reference="RElbow_Pitch">
    <kp>1000000.0</kp>
    <kd>100.0</kd>
    <mu1>30.0</mu1>
    <mu2>30.0</mu2>
    <maxVel>1.0</maxVel>
    <minDepth>0.001</minDepth>
    <material>Gazebo/White</material>
  </gazebo>
  <gazebo reference="RElbow_Yaw">
    <kp>1000000.0</kp>
    <kd>100.0</kd>
    <mu1>30.0</mu1>
    <mu2>30.0</mu2>
    <maxVel>1.0</maxVel>
    <minDepth>0.001</minDepth>
    <material>Gazebo/White</material>
  </gazebo>
  <gazebo reference="RWrist_Pitch">
    <kp>1000000.0</kp>
    <kd>100.0</kd>
    <mu1>30.0</mu1>
    <mu2>30.0</mu2>
    <maxVel>1.0</maxVel>
    <minDepth>0.001</minDepth>
    <material>Gazebo/White</material>
  </gazebo>
  <gazebo reference="RWrist_Roll">
    <kp>1000000.0</kp>
    <kd>100.0</kd>
    <mu1>30.0</mu1>
    <mu2>30.0</mu2>
    <maxVel>1.0</maxVel>
    <minDepth>0.001</minDepth>
    <material>Gazebo/White</material>
  </gazebo>
  <!-- ros_control plugin -->
  <gazebo>
    <plugin filename="libgazebo_ros_control.so" name="gazebo_ros_control">
      <robotNamespace>social_robot</robotNamespace>
      <controlPeriod>0.001</controlPeriod>
      <robotSimType>gazebo_ros_control/DefaultRobotHWSim</robotSimType>
    </plugin>
  </gazebo>
  <link name="base_footprint"/>
  <joint name="base_link" type="fixed">
    <parent link="base_footprint"/>
    <child link="base_link"/>
    <origin rpy="0 0 0" xyz="0.0 0.0 0.060"/>
  </joint>
  <!-- base link -->
  <link name="base_link">
    <inertial>
      <!--      <origin
        xyz="8.22653618212244E-06 0.160934490597598 -0.00189151304431439"
        rpy="0 0 0" />-->
      <origin rpy="0 0 1.57079632679" xyz="-0.160934490597598 8.22653618212244E-06 -0.00189151304431439"/>
      <mass value="9.16468890396806"/>
      <!--      <inertia
        ixx="0.368108530059628"
        ixy="-1.83664773050428E-06"
        ixz="5.85398093538166E-05"
        iyy="0.219775236597536"
        iyz="0.00269873784897349"
        izz="0.338690676992171" />-->
      <inertia ixx="0" ixy="0" ixz="0" iyy="0" iyz="0" izz="0"/>
    </inertial>
    <visual>
      <!--      <origin
        xyz="0 0 0"
        rpy="0 0 0" />-->
      <origin rpy="0 0 1.57079632679" xyz="0 0 0"/>
      <geometry>
        <mesh filename="package://social_robot_description/meshes/body/base_link.stl"/>
      </geometry>
      <material name="">
        <color rgba="0.752941176470588 0.752941176470588 0.752941176470588 1"/>
      </material>
    </visual>
    <collision>
      <!--      <origin
        xyz="0 0 0"
        rpy="0 0 0" />-->
      <origin rpy="0 0 1.57079632679" xyz="0 0 0"/>
      <geometry>
        <mesh filename="package://social_robot_description/meshes/body/base_link.stl"/>
      </geometry>
    </collision>
  </link>
  <!-- body -->
  <!-- waist roll joint -->
  <joint name="Waist_Roll" type="continuous">
    <!--    <origin
      xyz="0 0 0.579000000143115"
      rpy="1.5707963267949 0 0" />-->
    <origin rpy="0 0 0" xyz="0 0 0.579000000143115"/>
    <parent link="base_link"/>
    <child link="Waist_Roll"/>
    <axis xyz="1 0 0"/>
    <limit effort="30" lower="-0.348" upper="0.348" velocity="1.57"/>
    <safety_controller k_position="15" k_velocity="1.57" soft_lower_limit="-0.348" soft_upper_limit="0.348"/>
  </joint>
  <transmission name="Waist_Roll_tran">
    <type>transmission_interface/SimpleTransmission</type>
    <joint name="Waist_Roll">
      <hardwareInterface>hardware_interface/PositionJointInterface</hardwareInterface>
    </joint>
    <actuator name="Waist_Roll_motor">
      <hardwareInterface>hardware_interface/PositionJointInterface</hardwareInterface>
      <mechanicalReduction>1</mechanicalReduction>
    </actuator>
  </transmission>
  <!-- waist roll link -->
  <link name="Waist_Roll">
    <inertial>
      <!--      <origin
        xyz="-1.6981669084292E-15 0 -9.28958911114441E-07"
        rpy="0 0 0" />-->
      <origin rpy="1.57079632679 0 1.57079632679" xyz="-9.28958911114441E-07 -1.6981669084292E-15 0"/>
      <mass value="1.43675504024173"/>
      <inertia ixx="0" ixy="0" ixz="0" iyy="0" iyz="0" izz="0"/>
    </inertial>
    <visual>
      <!--      <origin
        xyz="0 0 0"
        rpy="0 0 0" />-->
      <origin rpy="1.57079632679 0 1.57079632679" xyz="0 0 0"/>
      <geometry>
        <mesh filename="package://social_robot_description/meshes/body/Waist_Roll.stl"/>
      </geometry>
      <material name="">
        <color rgba="0.792156862745098 0.819607843137255 0.933333333333333 1"/>
      </material>
    </visual>
    <collision>
      <!--      <origin
        xyz="0 0 0"
        rpy="0 0 0" />-->
      <origin rpy="1.57079632679 0 1.57079632679" xyz="0 0 0"/>
      <geometry>
        <mesh filename="package://social_robot_description/meshes/body/Waist_Roll.stl"/>
      </geometry>
    </collision>
  </link>
  <!-- waist pitch joint -->
  <joint name="Waist_Pitch" type="continuous">
    <origin rpy="0 0 0" xyz="0 0 0"/>
    <parent link="Waist_Roll"/>
    <child link="Waist_Pitch"/>
    <axis xyz="0 1 0"/>
    <limit effort="30" lower="-0.523" upper="0.523" velocity="1.57"/>
    <safety_controller k_position="15" k_velocity="1.57" soft_lower_limit="-0.523" soft_upper_limit="0.523"/>
  </joint>
  <transmission name="Waist_Pitch_tran">
    <type>transmission_interface/SimpleTransmission</type>
    <joint name="Waist_Pitch">
      <hardwareInterface>hardware_interface/PositionJointInterface</hardwareInterface>
    </joint>
    <actuator name="Waist_Pitch_motor">
      <hardwareInterface>hardware_interface/PositionJointInterface</hardwareInterface>
      <mechanicalReduction>1</mechanicalReduction>
    </actuator>
  </transmission>
  <!-- waist pitch link -->
  <link name="Waist_Pitch">
    <inertial>
      <!--      <origin
        xyz="1.46815175677656E-05 -0.0180187762940287 0.101257114843982 "
        rpy="0 0 0" />-->
      <origin rpy="1.57079632679 0 1.57079632679" xyz="0.101257114843982 1.46815175677656E-05 -0.0180187762940287 "/>
      <mass value="2.19862483991908"/>
      <!--      <inertia
        ixx="0.0366715993224349"
        ixy="1.89411704411262E-05"
        ixz="8.21451328972728E-06"
        iyy="0.00763973413946523"
        iyz="-0.00421453222211104"
        izz="0.0305991863005127" />-->
      <inertia ixx="0" ixy="0" ixz="0" iyy="0" iyz="0" izz="0"/>
    </inertial>
    <visual>
      <!--      <origin
        xyz="0 0 0"
        rpy="0 0 0" />-->
      <origin rpy="1.57079632679 0 1.57079632679" xyz="0 0 0"/>
      <geometry>
        <mesh filename="package://social_robot_description/meshes/body/Waist_Pitch.stl"/>
      </geometry>
      <material name="">
        <color rgba="0.752941176470588 0.752941176470588 0.752941176470588 1"/>
      </material>
    </visual>
    <collision>
      <!--      <origin
        xyz="0 0 0"
        rpy="0 0 0" />-->
      <origin rpy="1.57079632679 0 1.57079632679" xyz="0 0 0"/>
      <geometry>
        <mesh filename="package://social_robot_description/meshes/body/Waist_Pitch.stl"/>
      </geometry>
    </collision>
  </link>
  <!-- head yaw joint -->
  <joint name="Head_Yaw" type="revolute">
    <!--    <origin
      xyz="0 0.326000000000007 0.0119990710410899"
      rpy="0 0 0" />-->
    <origin rpy="0 0 0" xyz="0.0119990710410899 0 0.326000000000007"/>
    <parent link="Waist_Pitch"/>
    <child link="Head_Yaw"/>
    <axis xyz="0 0 1"/>
    <limit effort="30" lower="-1.57" upper="1.57" velocity="1.57"/>
    <safety_controller k_position="15" k_velocity="1.57" soft_lower_limit="-1.57" soft_upper_limit="1.57"/>
  </joint>
  <transmission name="Head_Yaw_tran">
    <type>transmission_interface/SimpleTransmission</type>
    <joint name="Head_Yaw">
      <hardwareInterface>hardware_interface/PositionJointInterface</hardwareInterface>
    </joint>
    <actuator name="Head_Yaw_motor">
      <hardwareInterface>hardware_interface/PositionJointInterface</hardwareInterface>
      <mechanicalReduction>1</mechanicalReduction>
    </actuator>
  </transmission>
  <!-- head yaw link -->
  <link name="Head_Yaw">
    <inertial>
      <!--      <origin
        xyz="-3.49815670899666E-08 0.0455597536621785 0.00282302245767964"
        rpy="0 0 0" />-->
      <origin rpy="1.57079632679 0 1.57079632679" xyz="0.00282302245767964 -3.49815670899666E-08 0.0455597536621785"/>
      <mass value="0.0486497311616148"/>
      <!--      <inertia
        ixx="2.66093638537384E-05"
        ixy="6.0429663771692E-12"
        ixz="-5.94440616689778E-11"
        iyy="2.63371860067501E-05"
        iyz="2.67738652169337E-06"
        izz="2.7217784725666E-07" />-->
      <inertia ixx="0" ixy="0" ixz="0" iyy="0" iyz="0" izz="0"/>
    </inertial>
    <visual>
      <!--      <origin
        xyz="0 0 0"
        rpy="0 0 0" />-->
      <origin rpy="1.57079632679 0 1.57079632679" xyz="0 0 0"/>
      <geometry>
        <mesh filename="package://social_robot_description/meshes/head/Head_Yaw.stl"/>
      </geometry>
      <material name="">
        <color rgba="0.796078431372549 0.823529411764706 0.937254901960784 1"/>
      </material>
    </visual>
    <collision>
      <!--      <origin
        xyz="0 0 0"
        rpy="0 0 0" />-->
      <origin rpy="1.57079632679 0 1.57079632679" xyz="0 0 0"/>
      <geometry>
        <mesh filename="package://social_robot_description/meshes/head/Head_Yaw.stl"/>
      </geometry>
    </collision>
  </link>
  <!-- head pitch joint -->
  <joint name="Head_Pitch" type="revolute">
    <!--    <origin
      xyz="0 0.0680000000000001 0"
      rpy="0 0 0" />-->
    <origin rpy="0 0 0" xyz="0 0 0.0680000000000001"/>
    <parent link="Head_Yaw"/>
    <child link="Head_Pitch"/>
    <axis xyz="0 1 0"/>
    <limit effort="30" lower="-0.348" upper="0.348" velocity="1.57"/>
    <safety_controller k_position="15" k_velocity="1.57" soft_lower_limit="-0.348" soft_upper_limit="0.348"/>
  </joint>
  <transmission name="Head_Pitch_tran">
    <type>transmission_interface/SimpleTransmission</type>
    <joint name="Head_Pitch">
      <hardwareInterface>hardware_interface/PositionJointInterface</hardwareInterface>
    </joint>
    <actuator name="Head_Pitch_motor">
      <hardwareInterface>hardware_interface/PositionJointInterface</hardwareInterface>
      <mechanicalReduction>1</mechanicalReduction>
    </actuator>
  </transmission>
  <!-- head pitch link -->
  <link name="Head_Pitch">
    <inertial>
      <!--      <origin
        xyz="0.00579062274498662 0.0936778317792072 0.00931349998338522"
        rpy="0 0 0" />-->
      <origin rpy="1.57079632679 0 1.57079632679" xyz="0.00931349998338522 0.00579062274498662 0.0936778317792072"/>
      <mass value="0.662230447574724"/>
      <!--<inertia
        ixx="0.00300992272201838"
        ixy="-0.000195456971244606"
        ixz="4.73982736539203E-05"
        iyy="0.00213791585174022"
        iyz="0.00026281169161505"
        izz="0.00230393404414791" />-->
      <inertia ixx="0" ixy="0" ixz="0" iyy="0" iyz="0" izz="0"/>
    </inertial>
    <visual>
      <!--      <origin
        xyz="0 0 0"
        rpy="0 0 0" />-->
      <origin rpy="1.57079632679 0 1.57079632679" xyz="0 0 0"/>
      <geometry>
        <mesh filename="package://social_robot_description/meshes/head/Head_Pitch.stl"/>
      </geometry>
      <material name="">
        <color rgba="0.752941176470588 0.752941176470588 0.752941176470588 1"/>
      </material>
    </visual>
    <collision>
      <!--      <origin
        xyz="0 0 0"
        rpy="0 0 0" />-->
      <origin rpy="1.57079632679 0 1.57079632679" xyz="0 0 0"/>
      <geometry>
        <mesh filename="package://social_robot_description/meshes/head/Head_Pitch.stl"/>
      </geometry>
    </collision>
  </link>
  <!-- left shoulder pitch joint -->
  <joint name="LShoulder_Pitch" type="revolute">
    <origin rpy="0 0 0" xyz="0 0.1065 0.2815"/>
    <parent link="Waist_Pitch"/>
    <child link="LShoulder_Pitch"/>
    <axis xyz="0 1 0"/>
    <limit effort="1000" lower="-2.82743338823" upper="2.82743338823" velocity="100"/>
    <dynamics damping="0.1" friction="0.0"/>
  </joint>
  <transmission name="LShoulder_Pitch_tran">
    <type>transmission_interface/SimpleTransmission</type>
    <joint name="LShoulder_Pitch">
      <hardwareInterface>hardware_interface/PositionJointInterface</hardwareInterface>
    </joint>
    <actuator name="LShoulder_Pitch_motor">
      <hardwareInterface>hardware_interface/PositionJointInterface</hardwareInterface>
      <mechanicalReduction>1</mechanicalReduction>
    </actuator>
  </transmission>
  <!-- left shoulder pitch link -->
  <link name="LShoulder_Pitch">
    <inertial>
      <origin rpy="0 0 0" xyz="4.6871137e-04 4.7922220e-02 -5.9742066e-07"/>
      <mass value="2.5802501e-01"/>
      <inertia ixx="7.8167957e-04" ixy="-6.2373043e-06" ixz="2.1638484e-09" iyy="1.0532761e-04" iyz="2.4776853e-09" izz="7.7621568e-04"/>
    </inertial>
    <visual>
      <origin rpy="0 0 0" xyz="0 0 0"/>
      <geometry>
        <mesh filename="package://social_robot_description/meshes/arm/la1.stl" scale="0.001 0.001 0.001"/>
      </geometry>
      <material name="">
        <color rgba="0.752941176470588 0.752941176470588 0.752941176470588 1"/>
      </material>
    </visual>
    <collision>
      <origin rpy="0 0 0" xyz="0 0 0"/>
      <geometry>
        <mesh filename="package://social_robot_description/meshes/arm/la1.stl" scale="0.001 0.001 0.001"/>
      </geometry>
    </collision>
  </link>
  <!-- left shoulder roll joint -->
  <joint name="LShoulder_Roll" type="revolute">
    <origin rpy="0 0 0" xyz="0 0.06375 0"/>
    <parent link="LShoulder_Pitch"/>
    <child link="LShoulder_Roll"/>
    <axis xyz="1 0 0"/>
    <limit effort="1000" lower="-2.82743338823" upper="2.82743338823" velocity="100"/>
    <dynamics damping="0.1" friction="0.0"/>
  </joint>
  <transmission name="LShoulder_Roll_tran">
    <type>transmission_interface/SimpleTransmission</type>
    <joint name="LShoulder_Roll">
      <hardwareInterface>hardware_interface/PositionJointInterface</hardwareInterface>
    </joint>
    <actuator name="LShoulder_Roll_motor">
      <hardwareInterface>hardware_interface/PositionJointInterface</hardwareInterface>
      <mechanicalReduction>1</mechanicalReduction>
    </actuator>
  </transmission>
  <!-- left shoulder roll link -->
  <link name="LShoulder_Roll">
    <inertial>
      <origin rpy="0 0 0" xyz="2.6047442e-5 6.9489221e-02 1.7513593e-05"/>
      <mass value="2.4899507e-01"/>
      <inertia ixx="1.5813034e-03" ixy="-3.2124803e-07" ixz="-7.2719573e-09" iyy="1.6009044e-04" iyz="2.6716959e-07" izz="1.6224156e-03"/>
    </inertial>
    <visual>
      <origin rpy="0 0 0" xyz="0 0 0"/>
      <geometry>
        <mesh filename="package://social_robot_description/meshes/arm/la2.stl" scale="0.001 0.001 0.001"/>
      </geometry>
      <material name="">
        <color rgba="0.752941176470588 0.752941176470588 0.752941176470588 1"/>
      </material>
    </visual>
    <collision>
      <origin rpy="0 0 0" xyz="0 0 0"/>
      <geometry>
        <mesh filename="package://social_robot_description/meshes/arm/la2.stl" scale="0.001 0.001 0.001"/>
      </geometry>
    </collision>
  </link>
  <!-- left elbow pitch joint -->
  <joint name="LElbow_Pitch" type="revolute">
    <origin rpy="0 0 0" xyz="0 0.09525 0"/>
    <parent link="LShoulder_Roll"/>
    <child link="LElbow_Pitch"/>
    <axis xyz="0 1 0"/>
    <limit effort="1000" lower="-2.82743338823" upper="2.82743338823" velocity="100"/>
    <dynamics damping="0.1" friction="0.0"/>
  </joint>
  <transmission name="LElbow_Pitch_tran">
    <type>transmission_interface/SimpleTransmission</type>
    <joint name="LElbow_Pitch">
      <hardwareInterface>hardware_interface/PositionJointInterface</hardwareInterface>
    </joint>
    <actuator name="LElbow_Pitch_motor">
      <hardwareInterface>hardware_interface/PositionJointInterface</hardwareInterface>
      <mechanicalReduction>1</mechanicalReduction>
    </actuator>
  </transmission>
  <!-- left elbow pitch link -->
  <link name="LElbow_Pitch">
    <inertial>
      <origin rpy="0 0 0" xyz="0.0 6.7026195e-02 5.2754282e-04"/>
      <mass value="2.2953581e-01"/>
      <inertia ixx="1.2018549e-03" ixy="0.0" ixz="0.0" iyy="6.9116644e-05" iyz="-8.9338855e-06" izz="1.1951211e-03"/>
    </inertial>
    <visual>
      <origin rpy="0 0 0" xyz="0 0 0"/>
      <geometry>
        <mesh filename="package://social_robot_description/meshes/arm/la3.stl" scale="0.001 0.001 0.001"/>
      </geometry>
      <material name="">
        <color rgba="0.752941176470588 0.752941176470588 0.752941176470588 1"/>
      </material>
    </visual>
    <collision>
      <origin rpy="0 0 0" xyz="0 0 0"/>
      <geometry>
        <mesh filename="package://social_robot_description/meshes/arm/la3.stl" scale="0.001 0.001 0.001"/>
      </geometry>
    </collision>
  </link>
  <!-- left elbow yaw joint -->
  <joint name="LElbow_Yaw" type="revolute">
    <origin rpy="0 0 0" xyz="0 0.086 0"/>
    <parent link="LElbow_Pitch"/>
    <child link="LElbow_Yaw"/>
    <axis xyz="0 0 1"/>
    <limit effort="1000" lower="-2.82743338823" upper="2.82743338823" velocity="100"/>
    <dynamics damping="0.1" friction="0.0"/>
  </joint>
  <transmission name="LElbow_Yaw_tran">
    <type>transmission_interface/SimpleTransmission</type>
    <joint name="LElbow_Yaw">
      <hardwareInterface>hardware_interface/PositionJointInterface</hardwareInterface>
    </joint>
    <actuator name="LElbow_Yaw_motor">
      <hardwareInterface>hardware_interface/PositionJointInterface</hardwareInterface>
      <mechanicalReduction>1</mechanicalReduction>
    </actuator>
  </transmission>
  <!-- left elbow yaw -->
  <link name="LElbow_Yaw">
    <inertial>
      <origin rpy="0 0 0" xyz="-2.2532640e-04 6.6117708e-02 2.7620342e-05"/>
      <mass value="2.3481741e-01"/>
      <inertia ixx="1.3412658e-03" ixy="8.1401171e-07" ixz="7.2713423e-09" iyy="1.4226184e-04" iyz="-2.7066590e-07" izz="1.3122537e-03"/>
    </inertial>
    <visual>
      <origin rpy="0 0 0" xyz="0 0 0"/>
      <geometry>
        <mesh filename="package://social_robot_description/meshes/arm/la4.stl" scale="0.001 0.001 0.001"/>
      </geometry>
      <material name="">
        <color rgba="0.752941176470588 0.752941176470588 0.752941176470588 1"/>
      </material>
    </visual>
    <collision>
      <origin rpy="0 0 0" xyz="0 0 0"/>
      <geometry>
        <mesh filename="package://social_robot_description/meshes/arm/la4.stl" scale="0.001 0.001 0.001"/>
      </geometry>
    </collision>
  </link>
  <!-- left wrist pitch joint -->
  <joint name="LWrist_Pitch" type="revolute">
    <origin rpy="0 0 0" xyz="0 0.08745 0"/>
    <parent link="LElbow_Yaw"/>
    <child link="LWrist_Pitch"/>
    <axis xyz="0 1 0"/>
    <limit effort="1000" lower="-2.82743338823" upper="2.82743338823" velocity="100"/>
    <dynamics damping="0.1" friction="0.0"/>
  </joint>
  <transmission name="LWrist_Pitch_tran">
    <type>transmission_interface/SimpleTransmission</type>
    <joint name="LWrist_Pitch">
      <hardwareInterface>hardware_interface/PositionJointInterface</hardwareInterface>
    </joint>
    <actuator name="LWrist_Pitch_motor">
      <hardwareInterface>hardware_interface/PositionJointInterface</hardwareInterface>
      <mechanicalReduction>1</mechanicalReduction>
    </actuator>
  </transmission>
  <!-- left wrist pitch link -->
  <link name="LWrist_Pitch">
    <inertial>
      <origin rpy="0 0 0" xyz="4.0281206e-04 5.8804030e-02 0.0000000e+00"/>
      <mass value="1.3034150e-01"/>
      <inertia ixx="5.3537399e-04" ixy="-3.4499040e-06" ixz="0.0" iyy="2.8340595e-05" iyz="0.0" izz="8.2859645e-05"/>
    </inertial>
    <visual>
      <origin rpy="0 0 0" xyz="0 0 0"/>
      <geometry>
        <mesh filename="package://social_robot_description/meshes/arm/la5.stl" scale="0.001 0.001 0.001"/>
      </geometry>
      <material name="">
        <color rgba="0.752941176470588 0.752941176470588 0.752941176470588 1"/>
      </material>
    </visual>
    <collision>
      <origin rpy="0 0 0" xyz="0 0 0"/>
      <geometry>
        <mesh filename="package://social_robot_description/meshes/arm/la5.stl" scale="0.001 0.001 0.001"/>
      </geometry>
    </collision>
  </link>
  <!-- left wrist roll joint -->
  <joint name="LWrist_Roll" type="revolute">
    <origin rpy="0 0 0" xyz="0 0.07655 0"/>
    <parent link="LWrist_Pitch"/>
    <child link="LWrist_Roll"/>
    <axis xyz="1 0 0"/>
    <limit effort="1000" lower="-2.82743338823" upper="2.82743338823" velocity="100"/>
    <dynamics damping="0.1" friction="0.0"/>
  </joint>
  <transmission name="LWrist_Roll_tran">
    <type>transmission_interface/SimpleTransmission</type>
    <joint name="LWrist_Roll">
      <hardwareInterface>hardware_interface/PositionJointInterface</hardwareInterface>
    </joint>
    <actuator name="LWrist_Roll_motor">
      <hardwareInterface>hardware_interface/PositionJointInterface</hardwareInterface>
      <mechanicalReduction>1</mechanicalReduction>
    </actuator>
  </transmission>
  <!-- left wrist pitch link -->
  <link name="LWrist_Roll">
    <inertial>
      <origin rpy="0 0 0" xyz="-1.8349932e-04 5.6144496e-02 -4.1957881e-04"/>
      <mass value="2.7446277e-01"/>
      <inertia ixx="1.1260251e-03" ixy="3.3427263e-06" ixz="-2.4984424e-05" iyy="2.1609604e-04" iyz="1.0322979e-05" izz="1.0780524e-03"/>
    </inertial>
    <visual>
      <origin rpy="0 0 0" xyz="0 0 0"/>
      <geometry>
        <mesh filename="package://social_robot_description/meshes/arm/la6-2.stl" scale="0.001 0.001 0.001"/>
      </geometry>
      <material name="">
        <color rgba="0.752941176470588 0.752941176470588 0.752941176470588 1"/>
      </material>
    </visual>
    <collision>
      <origin rpy="0 0 0" xyz="0 0 0"/>
      <geometry>
        <mesh filename="package://social_robot_description/meshes/arm/la6-2.stl" scale="0.001 0.001 0.001"/>
      </geometry>
    </collision>
  </link>
  <!-- end effect point -->
  <joint name="left_end_effect_point" type="fixed">
    <origin rpy="0 0 0" xyz="0.0 0.109 0.0"/>
    <parent link="LWrist_Roll"/>
    <child link="left_end_effect_point"/>
  </joint>
  <!-- end effect point -->
  <link name="left_end_effect_point">
    <visual>
      <origin rpy="0 0 0" xyz="0 0 0"/>
      <geometry>
        <box size="0.01 0.01 0.01"/>
      </geometry>
      <material name="">
        <color rgba="0.8 0.0 0.0 1.0"/>
      </material>
    </visual>
    <inertial>
      <origin rpy="0 0 0" xyz="0.0 0.0 0.0"/>
      <mass value="0.001"/>
      <inertia ixx="1.0e-06" ixy="0.0" ixz="0.0" iyy="1.0e-06" iyz="0.0" izz="1.0e-06"/>
    </inertial>
  </link>
  <!-- left finger 1 joint -->
  <joint name="LFinger_1" type="revolute">
    <origin rpy="0 0 0" xyz="0.027 0.07275 0.0113"/>
    <parent link="LWrist_Roll"/>
    <child link="LFinger_1"/>
    <axis xyz="1 0 0"/>
    <limit effort="1000" lower="-2.82743338823" upper="2.82743338823" velocity="100"/>
    <dynamics damping="0.1" friction="0.0"/>
  </joint>
  <transmission name="LFinger_1_tran">
    <type>transmission_interface/SimpleTransmission</type>
    <joint name="LFinger_1">
      <hardwareInterface>hardware_interface/PositionJointInterface</hardwareInterface>
    </joint>
    <actuator name="LFinger_1_motor">
      <hardwareInterface>hardware_interface/PositionJointInterface</hardwareInterface>
      <mechanicalReduction>1</mechanicalReduction>
    </actuator>
  </transmission>
  <!-- left finger 1 link -->
  <link name="LFinger_1">
    <inertial>
      <origin rpy="0 0 0" xyz="-8.2704221e-03 4.8253759e-02 1.0973580e-02"/>
      <mass value="1.7073271e-02"/>
      <inertia ixx="4.9993780e-05" ixy="7.3320922e-06" ixz="1.6291877e-06" iyy="4.6481624e-06" iyz="-8.4785956e-06" izz="4.8754194e-05"/>
    </inertial>
    <visual>
      <origin rpy="0 0 0" xyz="0 0 0"/>
      <geometry>
        <mesh filename="package://social_robot_description/meshes/hand/lf1.stl" scale="0.001 0.001 0.001"/>
      </geometry>
      <material name="">
        <color rgba="0.752941176470588 0.752941176470588 0.752941176470588 1"/>
      </material>
    </visual>
    <collision>
      <origin rpy="0 0 0" xyz="0 0 0"/>
      <geometry>
        <mesh filename="package://social_robot_description/meshes/hand/lf1.stl" scale="0.001 0.001 0.001"/>
      </geometry>
    </collision>
  </link>
  <!-- left finger 2 joint -->
  <joint name="LFinger_2" type="revolute">
    <origin rpy="0 0 0" xyz="-0.014 0.07275 0.0113"/>
    <parent link="LWrist_Roll"/>
    <child link="LFinger_2"/>
    <axis xyz="1 0 0"/>
    <limit effort="1000" lower="-2.82743338823" upper="2.82743338823" velocity="100"/>
    <dynamics damping="0.1" friction="0.0"/>
  </joint>
  <transmission name="LFinger_2_tran">
    <type>transmission_interface/SimpleTransmission</type>
    <joint name="LFinger_2">
      <hardwareInterface>hardware_interface/PositionJointInterface</hardwareInterface>
    </joint>
    <actuator name="LFinger_2_motor">
      <hardwareInterface>hardware_interface/PositionJointInterface</hardwareInterface>
      <mechanicalReduction>1</mechanicalReduction>
    </actuator>
  </transmission>
  <!-- left finger 2 link -->
  <link name="LFinger_2">
    <inertial>
      <origin rpy="0 0 0" xyz="5.2010384e-03 4.7810269e-02 1.0862160e-02"/>
      <mass value="1.7225011e-02"/>
      <inertia ixx="4.9997716e-05" ixy="4.8602561e-06" ixz="-1.0665523e-06" iyy="3.9576862e-06" iyz="-8.4761831e-06" izz="4.8062973e-05"/>
    </inertial>
    <visual>
      <origin rpy="0 0 0" xyz="0 0 0"/>
      <geometry>
        <mesh filename="package://social_robot_description/meshes/hand/lf2.stl" scale="0.001 0.001 0.001"/>
      </geometry>
      <material name="">
        <color rgba="0.752941176470588 0.752941176470588 0.752941176470588 1"/>
      </material>
    </visual>
    <collision>
      <origin rpy="0 0 0" xyz="0 0 0"/>
      <geometry>
        <mesh filename="package://social_robot_description/meshes/hand/lf2.stl" scale="0.001 0.001 0.001"/>
      </geometry>
    </collision>
  </link>
  <!-- left finger 3 joint -->
  <joint name="LFinger_3" type="revolute">
    <origin rpy="0 0 0" xyz="-0.0305 0.07275 -0.02112"/>
    <parent link="LWrist_Roll"/>
    <child link="LFinger_3"/>
    <axis xyz="1 0 0"/>
    <limit effort="1000" lower="-2.82743338823" upper="2.82743338823" velocity="100"/>
    <dynamics damping="0.1" friction="0.0"/>
  </joint>
  <transmission name="LFinger_3_tran">
    <type>transmission_interface/SimpleTransmission</type>
    <joint name="LFinger_3">
      <hardwareInterface>hardware_interface/PositionJointInterface</hardwareInterface>
    </joint>
    <actuator name="LFinger_3_motor">
      <hardwareInterface>hardware_interface/PositionJointInterface</hardwareInterface>
      <mechanicalReduction>1</mechanicalReduction>
    </actuator>
  </transmission>
  <!-- left finger 3 link -->
  <link name="LFinger_3">
    <inertial>
      <origin rpy="0 0 0" xyz="2.7413473e-02 4.7251197e-02 -9.9474237e-03"/>
      <mass value="4.0458040e-02"/>
      <inertia ixx="1.1427275e-04" ixy="-5.3019501e-05" ixz="1.1103006e-05" iyy="5.3733214e-05" iyz="1.7007112e-05" izz="1.5502670e-04"/>
    </inertial>
    <visual>
      <origin rpy="0 0 0" xyz="0 0 0"/>
      <geometry>
        <mesh filename="package://social_robot_description/meshes/hand/lf3.stl" scale="0.001 0.001 0.001"/>
      </geometry>
      <material name="">
        <color rgba="0.752941176470588 0.752941176470588 0.752941176470588 1"/>
      </material>
    </visual>
    <collision>
      <origin rpy="0 0 0" xyz="0 0 0"/>
      <geometry>
        <mesh filename="package://social_robot_description/meshes/hand/lf3.stl" scale="0.001 0.001 0.001"/>
      </geometry>
    </collision>
  </link>
  <!-- right shoulder pitch joint -->
  <joint name="RShoulder_Pitch" type="revolute">
    <origin rpy="0 0 0" xyz="0 -0.1065 0.2815"/>
    <parent link="Waist_Pitch"/>
    <child link="RShoulder_Pitch"/>
    <axis xyz="0 1 0"/>
    <limit effort="1000" lower="-2.82743338823" upper="2.82743338823" velocity="100"/>
    <dynamics damping="0.1" friction="0.0"/>
  </joint>
  <transmission name="RShoulder_Pitch_tran">
    <type>transmission_interface/SimpleTransmission</type>
    <joint name="RShoulder_Pitch">
      <hardwareInterface>hardware_interface/PositionJointInterface</hardwareInterface>
    </joint>
    <actuator name="RShoulder_Pitch_motor">
      <hardwareInterface>hardware_interface/PositionJointInterface</hardwareInterface>
      <mechanicalReduction>1</mechanicalReduction>
    </actuator>
  </transmission>
  <!-- right shoulder pitch link -->
  <link name="RShoulder_Pitch">
    <inertial>
      <origin rpy="0 0 0" xyz="4.6871137e-04 -4.7922220e-02 -5.9742066e-07"/>
      <mass value="2.5106828E-01"/>
      <inertia ixx="7.8167957e-04" ixy="6.2373043e-06" ixz="2.1638484e-09" iyy="1.0532761e-04" iyz="-2.4776853e-09" izz="7.7621568e-04"/>
    </inertial>
    <visual>
      <origin rpy="0 0 0" xyz="0 0 0"/>
      <geometry>
        <mesh filename="package://social_robot_description/meshes/arm/ra1.stl" scale="0.001 0.001 0.001"/>
      </geometry>
      <material name="">
        <color rgba="0.752941176470588 0.752941176470588 0.752941176470588 1"/>
      </material>
    </visual>
    <collision>
      <origin rpy="0 0 0" xyz="0 0 0"/>
      <geometry>
        <mesh filename="package://social_robot_description/meshes/arm/ra1.stl" scale="0.001 0.001 0.001"/>
      </geometry>
    </collision>
  </link>
  <!-- right shoulder roll joint -->
  <joint name="RShoulder_Roll" type="revolute">
    <origin rpy="0 0 0" xyz="0 -0.06375 0"/>
    <parent link="RShoulder_Pitch"/>
    <child link="RShoulder_Roll"/>
    <axis xyz="1 0 0"/>
    <limit effort="1000" lower="-2.82743338823" upper="2.82743338823" velocity="100"/>
    <dynamics damping="0.1" friction="0.0"/>
  </joint>
  <transmission name="RShoulder_Roll_tran">
    <type>transmission_interface/SimpleTransmission</type>
    <joint name="RShoulder_Roll">
      <hardwareInterface>hardware_interface/PositionJointInterface</hardwareInterface>
    </joint>
    <actuator name="RShoulder_Roll_motor">
      <hardwareInterface>hardware_interface/PositionJointInterface</hardwareInterface>
      <mechanicalReduction>1</mechanicalReduction>
    </actuator>
  </transmission>
  <!-- right shoulder roll link -->
  <link name="RShoulder_Roll">
    <inertial>
      <origin rpy="0 0 0" xyz="2.6047442e-5 -6.9489221e-02 1.7513593e-05"/>
      <mass value="2.4899507e-01"/>
      <inertia ixx="1.5813034e-03" ixy="3.2124803e-07" ixz="-7.2719573e-09" iyy="1.6009044e-04" iyz="-2.6716959e-07" izz="1.6224156e-03"/>
    </inertial>
    <visual>
      <origin rpy="0 0 0" xyz="0 0 0"/>
      <geometry>
        <mesh filename="package://social_robot_description/meshes/arm/ra2.stl" scale="0.001 0.001 0.001"/>
      </geometry>
      <material name="">
        <color rgba="0.752941176470588 0.752941176470588 0.752941176470588 1"/>
      </material>
    </visual>
    <collision>
      <origin rpy="0 0 0" xyz="0 0 0"/>
      <geometry>
        <mesh filename="package://social_robot_description/meshes/arm/ra2.stl" scale="0.001 0.001 0.001"/>
      </geometry>
    </collision>
  </link>
  <!-- right elbow pitch joint -->
  <joint name="RElbow_Pitch" type="revolute">
    <origin rpy="0 0 0" xyz="0 -0.09525 0"/>
    <parent link="RShoulder_Roll"/>
    <child link="RElbow_Pitch"/>
    <axis xyz="0 1 0"/>
    <limit effort="1000" lower="-2.82743338823" upper="2.82743338823" velocity="100"/>
    <dynamics damping="0.1" friction="0.0"/>
  </joint>
  <transmission name="RElbow_Pitch_tran">
    <type>transmission_interface/SimpleTransmission</type>
    <joint name="RElbow_Pitch">
      <hardwareInterface>hardware_interface/PositionJointInterface</hardwareInterface>
    </joint>
    <actuator name="RElbow_Pitch_motor">
      <hardwareInterface>hardware_interface/PositionJointInterface</hardwareInterface>
      <mechanicalReduction>1</mechanicalReduction>
    </actuator>
  </transmission>
  <!-- right elbow pitch link -->
  <link name="RElbow_Pitch">
    <inertial>
      <origin rpy="0 0 0" xyz="0.0 -6.7026195e-02 5.2754282e-04"/>
      <mass value="2.2953581e-01"/>
      <inertia ixx="1.2018549e-03" ixy="0.0" ixz="0.0" iyy="6.9116644e-05" iyz="8.9338855e-06" izz="1.1951211e-03"/>
    </inertial>
    <visual>
      <origin rpy="0 0 0" xyz="0 0 0"/>
      <geometry>
        <mesh filename="package://social_robot_description/meshes/arm/ra3.stl" scale="0.001 0.001 0.001"/>
      </geometry>
      <material name="">
        <color rgba="0.752941176470588 0.752941176470588 0.752941176470588 1"/>
      </material>
    </visual>
    <collision>
      <origin rpy="0 0 0" xyz="0 0 0"/>
      <geometry>
        <mesh filename="package://social_robot_description/meshes/arm/ra3.stl" scale="0.001 0.001 0.001"/>
      </geometry>
    </collision>
  </link>
  <!-- right elbow yaw joint -->
  <joint name="RElbow_Yaw" type="revolute">
    <origin rpy="0 0 0" xyz="0 -0.086 0"/>
    <parent link="RElbow_Pitch"/>
    <child link="RElbow_Yaw"/>
    <axis xyz="0 0 1"/>
    <limit effort="1000" lower="-2.82743338823" upper="2.82743338823" velocity="100"/>
    <dynamics damping="0.1" friction="0.0"/>
  </joint>
  <transmission name="RElbow_Yaw_tran">
    <type>transmission_interface/SimpleTransmission</type>
    <joint name="RElbow_Yaw">
      <hardwareInterface>hardware_interface/PositionJointInterface</hardwareInterface>
    </joint>
    <actuator name="RElbow_Yaw_motor">
      <hardwareInterface>hardware_interface/PositionJointInterface</hardwareInterface>
      <mechanicalReduction>1</mechanicalReduction>
    </actuator>
  </transmission>
  <!-- right elbow yaw -->
  <link name="RElbow_Yaw">
    <inertial>
      <origin rpy="0 0 0" xyz="-2.2532640e-04 -6.6117708e-02 2.7620342e-05"/>
      <mass value="2.3481741e-01"/>
      <inertia ixx="1.3412658e-03" ixy="-8.1401171e-07" ixz="7.2713423e-09" iyy="1.4226184e-04" iyz="2.7066590e-07" izz="1.3122537e-03"/>
    </inertial>
    <visual>
      <origin rpy="0 0 0" xyz="0 0 0"/>
      <geometry>
        <mesh filename="package://social_robot_description/meshes/arm/ra4.stl" scale="0.001 0.001 0.001"/>
      </geometry>
      <material name="">
        <color rgba="0.752941176470588 0.752941176470588 0.752941176470588 1"/>
      </material>
    </visual>
    <collision>
      <origin rpy="0 0 0" xyz="0 0 0"/>
      <geometry>
        <mesh filename="package://social_robot_description/meshes/arm/ra4.stl" scale="0.001 0.001 0.001"/>
      </geometry>
    </collision>
  </link>
  <!-- right wrist pitch joint -->
  <joint name="RWrist_Pitch" type="revolute">
    <origin rpy="0 0 0" xyz="0 -0.08745 0"/>
    <parent link="RElbow_Yaw"/>
    <child link="RWrist_Pitch"/>
    <axis xyz="0 1 0"/>
    <limit effort="1000" lower="-2.82743338823" upper="2.82743338823" velocity="100"/>
    <dynamics damping="0.1" friction="0.0"/>
  </joint>
  <transmission name="RWrist_Pitch_tran">
    <type>transmission_interface/SimpleTransmission</type>
    <joint name="RWrist_Pitch">
      <hardwareInterface>hardware_interface/PositionJointInterface</hardwareInterface>
    </joint>
    <actuator name="RWrist_Pitch_motor">
      <hardwareInterface>hardware_interface/PositionJointInterface</hardwareInterface>
      <mechanicalReduction>1</mechanicalReduction>
    </actuator>
  </transmission>
  <!-- right wrist pitch link -->
  <link name="RWrist_Pitch">
    <inertial>
      <origin rpy="0 0 0" xyz="4.0281206e-04 -5.8804030e-02 0.0"/>
      <mass value="1.3034150e-01"/>
      <inertia ixx="5.3537399e-04" ixy="34499040e-06" ixz="0.0" iyy="2.8340595e-05" iyz="0.0" izz="5.3359047e-04"/>
    </inertial>
    <visual>
      <origin rpy="0 0 0" xyz="0 0 0"/>
      <geometry>
        <mesh filename="package://social_robot_description/meshes/arm/ra5.stl" scale="0.001 0.001 0.001"/>
      </geometry>
      <material name="">
        <color rgba="0.752941176470588 0.752941176470588 0.752941176470588 1"/>
      </material>
    </visual>
    <collision>
      <origin rpy="0 0 0" xyz="0 0 0"/>
      <geometry>
        <mesh filename="package://social_robot_description/meshes/arm/ra5.stl" scale="0.001 0.001 0.001"/>
      </geometry>
    </collision>
  </link>
  <!-- right finger joint -->
  <joint name="RWrist_Roll" type="revolute">
    <origin rpy="0 0 0" xyz="0 -0.07655 0"/>
    <parent link="RWrist_Pitch"/>
    <child link="RWrist_Roll"/>
    <axis xyz="1 0 0"/>
    <limit effort="1000" lower="-2.82743338823" upper="2.82743338823" velocity="100"/>
    <dynamics damping="0.1" friction="0.0"/>
  </joint>
  <transmission name="RWrist_Roll_tran">
    <type>transmission_interface/SimpleTransmission</type>
    <joint name="RWrist_Roll">
      <hardwareInterface>hardware_interface/PositionJointInterface</hardwareInterface>
    </joint>
    <actuator name="RWrist_Roll_motor">
      <hardwareInterface>hardware_interface/PositionJointInterface</hardwareInterface>
      <mechanicalReduction>1</mechanicalReduction>
    </actuator>
  </transmission>
  <!-- right finger link -->
  <link name="RWrist_Roll">
    <inertial>
      <origin rpy="0 0 0" xyz="-1.8349932e-04 -5.6144496e-02 -4.1957881e-04"/>
      <mass value="2.7446277e-01"/>
      <inertia ixx="1.1260251e-03" ixy="-3.3427263e-06" ixz="-2.4984424e-05" iyy="2.1609604e-04" iyz="-1.0322979e-05" izz="1.0780524e-03"/>
    </inertial>
    <visual>
      <origin rpy="0 0 0" xyz="0 0 0"/>
      <geometry>
        <mesh filename="package://social_robot_description/meshes/arm/ra6-2.stl" scale="0.001 0.001 0.001"/>
      </geometry>
      <material name="">
        <color rgba="0.752941176470588 0.752941176470588 0.752941176470588 1"/>
      </material>
    </visual>
    <collision>
      <origin rpy="0 0 0" xyz="0 0 0"/>
      <geometry>
        <mesh filename="package://social_robot_description/meshes/arm/ra6-2.stl" scale="0.001 0.001 0.001"/>
      </geometry>
    </collision>
  </link>
  <!-- end effect point -->
  <joint name="right_end_effect_point" type="fixed">
    <origin rpy="0 0 0" xyz="0.0 -0.109 0.0"/>
    <parent link="RWrist_Roll"/>
    <child link="right_end_effect_point"/>
  </joint>
  <!-- end effect point -->
  <link name="right_end_effect_point">
    <visual>
      <origin rpy="0 0 0" xyz="0 0 0"/>
      <geometry>
        <box size="0.01 0.01 0.01"/>
      </geometry>
      <material name="">
        <color rgba="0.8 0.0 0.0 1.0"/>
      </material>
    </visual>
    <inertial>
      <origin rpy="0 0 0" xyz="0.0 0.0 0.0"/>
      <mass value="0.001"/>
      <inertia ixx="1.0e-06" ixy="0.0" ixz="0.0" iyy="1.0e-06" iyz="0.0" izz="1.0e-06"/>
    </inertial>
  </link>
  <!-- right finger 1 joint -->
  <joint name="RFinger_1" type="revolute">
    <origin rpy="0 0 0" xyz="0.027 -0.07275 0.0113"/>
    <parent link="RWrist_Roll"/>
    <child link="RFinger_1"/>
    <axis xyz="1 0 0"/>
    <limit effort="1000" lower="-2.82743338823" upper="2.82743338823" velocity="100"/>
    <dynamics damping="0.1" friction="0.0"/>
  </joint>
  <transmission name="RFinger_1_tran">
    <type>transmission_interface/SimpleTransmission</type>
    <joint name="RFinger_1">
      <hardwareInterface>hardware_interface/PositionJointInterface</hardwareInterface>
    </joint>
    <actuator name="RFinger_1_motor">
      <hardwareInterface>hardware_interface/PositionJointInterface</hardwareInterface>
      <mechanicalReduction>1</mechanicalReduction>
    </actuator>
  </transmission>
  <!-- right finger 1 link -->
  <link name="RFinger_1">
    <inertial>
      <origin rpy="0 0 0" xyz="-8.2704221e-03 -4.8253759e-02 1.0973580e-02"/>
      <mass value="1.7073271e-02"/>
      <inertia ixx="4.9993780e-05" ixy="-7.3320922e-06" ixz="1.6291877e-06" iyy="4.6481624e-06" iyz="8.4785956e-06" izz="4.8754194e-05"/>
    </inertial>
    <visual>
      <origin rpy="0 0 0" xyz="0 0 0"/>
      <geometry>
        <mesh filename="package://social_robot_description/meshes/hand/rf1.stl" scale="0.001 0.001 0.001"/>
      </geometry>
      <material name="">
        <color rgba="0.752941176470588 0.752941176470588 0.752941176470588 1"/>
      </material>
    </visual>
    <collision>
      <origin rpy="0 0 0" xyz="0 0 0"/>
      <geometry>
        <mesh filename="package://social_robot_description/meshes/hand/rf1.stl" scale="0.001 0.001 0.001"/>
      </geometry>
    </collision>
  </link>
  <!-- right finger 2 joint -->
  <joint name="RFinger_2" type="revolute">
    <origin rpy="0 0 0" xyz="-0.014 -0.07275 0.0113"/>
    <parent link="RWrist_Roll"/>
    <child link="RFinger_2"/>
    <axis xyz="1 0 0"/>
    <limit effort="1000" lower="-2.82743338823" upper="2.82743338823" velocity="100"/>
    <dynamics damping="0.1" friction="0.0"/>
  </joint>
  <transmission name="RFinger_2_tran">
    <type>transmission_interface/SimpleTransmission</type>
    <joint name="RFinger_2">
      <hardwareInterface>hardware_interface/PositionJointInterface</hardwareInterface>
    </joint>
    <actuator name="RFinger_2_motor">
      <hardwareInterface>hardware_interface/PositionJointInterface</hardwareInterface>
      <mechanicalReduction>1</mechanicalReduction>
    </actuator>
  </transmission>
  <!-- right finger 2 link -->
  <link name="RFinger_2">
    <inertial>
      <origin rpy="0 0 0" xyz="5.2010384e-03 -4.7810269e-02 1.0862160e-02"/>
      <mass value="1.7225011e-02"/>
      <inertia ixx="4.9997716e-05" ixy="-4.8602561e-06" ixz="-1.0665523e-06" iyy="3.9576862e-06" iyz="8.4761831e-06" izz="4.8062973e-05"/>
    </inertial>
    <visual>
      <origin rpy="0 0 0" xyz="0 0 0"/>
      <geometry>
        <mesh filename="package://social_robot_description/meshes/hand/rf2.stl" scale="0.001 0.001 0.001"/>
      </geometry>
      <material name="">
        <color rgba="0.752941176470588 0.752941176470588 0.752941176470588 1"/>
      </material>
    </visual>
    <collision>
      <origin rpy="0 0 0" xyz="0 0 0"/>
      <geometry>
        <mesh filename="package://social_robot_description/meshes/hand/rf2.stl" scale="0.001 0.001 0.001"/>
      </geometry>
    </collision>
  </link>
  <!-- right finger 3 joint -->
  <joint name="RFinger_3" type="revolute">
    <origin rpy="0 0 0" xyz="-0.0305 -0.07275 -0.02112"/>
    <parent link="RWrist_Roll"/>
    <child link="RFinger_3"/>
    <axis xyz="1 0 0"/>
    <limit effort="1000" lower="-2.82743338823" upper="2.82743338823" velocity="100"/>
    <dynamics damping="0.1" friction="0.0"/>
  </joint>
  <transmission name="RFinger_3_tran">
    <type>transmission_interface/SimpleTransmission</type>
    <joint name="RFinger_3">
      <hardwareInterface>hardware_interface/PositionJointInterface</hardwareInterface>
    </joint>
    <actuator name="RFinger_3_motor">
      <hardwareInterface>hardware_interface/PositionJointInterface</hardwareInterface>
      <mechanicalReduction>1</mechanicalReduction>
    </actuator>
  </transmission>
  <!-- right finger 3 link -->
  <link name="RFinger_3">
    <inertial>
      <origin rpy="0 0 0" xyz="2.7413473e-02 -4.7251197e-02 -9.9474237e-03"/>
      <mass value="4.0458040e-02"/>
      <inertia ixx="1.1427275e-04" ixy="5.3019501e-05" ixz="1.1103006e-05" iyy="5.3733214e-05" iyz="-1.7007112e-05" izz="1.5502670e-04"/>
    </inertial>
    <visual>
      <origin rpy="0 0 0" xyz="0 0 0"/>
      <geometry>
        <mesh filename="package://social_robot_description/meshes/hand/rf3.stl" scale="0.001 0.001 0.001"/>
      </geometry>
      <material name="">
        <color rgba="0.752941176470588 0.752941176470588 0.752941176470588 1"/>
      </material>
    </visual>
    <collision>
      <origin rpy="0 0 0" xyz="0 0 0"/>
      <geometry>
        <mesh filename="package://social_robot_description/meshes/hand/rf3.stl" scale="0.001 0.001 0.001"/>
      </geometry>
    </collision>
  </link>
</robot>

